<?xml version="1.0" encoding="utf-8"?>
<!-- This URDF was automatically created by SolidWorks to URDF Exporter! Originally created by Stephen Brawner (brawner@gmail.com) 
     Commit Version: 1.6.0-4-g7f85cfe  Build Version: 1.6.7995.38578
     For more information, please see http://wiki.ros.org/sw_urdf_exporter -->
<robot
  name="SkyGrip_URDF">
  <link
    name="base_link">
    <inertial>
      <origin
        xyz="0.10107 -0.033604 0.041506"
        rpy="0 0 0" />
      <mass
        value="1" />
      <inertia
        ixx="0.0040901"
        ixy="1.3275E-05"
        ixz="-5.9029E-08"
        iyy="0.0055802"
        iyz="-4.2589E-06"
        izz="0.0094981" />
    </inertial>
    <visual>
      <origin
        xyz="0 0 0"
        rpy="0 0 0" />
      <geometry>
        <mesh
          filename="package://SkyGrip_URDF/meshes/base_link.STL" />
      </geometry>
      <material
        name="">
        <color
          rgba="0.79216 0.81961 0.93333 1" />
      </material>
    </visual>
    <collision>
      <origin
        xyz="0 0 0"
        rpy="0 0 0" />
      <geometry>
        <mesh
          filename="package://SkyGrip_URDF/meshes/base_link.STL" />
      </geometry>
    </collision>
  </link>
  <link
    name="Link_1">
    <inertial>
      <origin
        xyz="0.023497 -7.0854E-06 -0.08892"
        rpy="0 0 0" />
      <mass
        value="0.08" />
      <inertia
        ixx="1.7491E-05"
        ixy="-5.233E-09"
        ixz="2.555E-07"
        iyy="2.2905E-05"
        iyz="4.4082E-09"
        izz="1.2229E-05" />
    </inertial>
    <visual>
      <origin
        xyz="0 0 0"
        rpy="0 0 0" />
      <geometry>
        <mesh
          filename="package://SkyGrip_URDF/meshes/Link_1.STL" />
      </geometry>
      <material
        name="">
        <color
          rgba="1 0.94902 0.89804 1" />
      </material>
    </visual>
    <collision>
      <origin
        xyz="0 0 0"
        rpy="0 0 0" />
      <geometry>
        <mesh
          filename="package://SkyGrip_URDF/meshes/Link_1.STL" />
      </geometry>
    </collision>
  </link>
  <joint
    name="Joint_1"
    type="continuous">
    <origin
      xyz="0.075884 -0.042123 -0.023898"
      rpy="-0.00065513 0 -0.0087266" />
    <parent
      link="base_link" />
    <child
      link="Link_1" />
    <axis
      xyz="1 0 0" />
    <limit
      lower="-0.8"
      upper="0.8"
      effort="0"
      velocity="0" />
  </joint>
  <link
    name="Link_2">
    <inertial>
      <origin
        xyz="0.023165 -1.3323E-15 0.079412"
        rpy="0 0 0" />
      <mass
        value="0.105" />
      <inertia
        ixx="4.0466E-05"
        ixy="9.0262E-20"
        ixz="-7.0184E-20"
        iyy="4.165E-05"
        iyz="2.039E-19"
        izz="2.8062E-05" />
    </inertial>
    <visual>
      <origin
        xyz="0 0 0"
        rpy="0 0 0" />
      <geometry>
        <mesh
          filename="package://SkyGrip_URDF/meshes/Link_2.STL" />
      </geometry>
      <material
        name="">
        <color
          rgba="1 1 1 1" />
      </material>
    </visual>
    <collision>
      <origin
        xyz="0 0 0"
        rpy="0 0 0" />
      <geometry>
        <mesh
          filename="package://SkyGrip_URDF/meshes/Link_2.STL" />
      </geometry>
    </collision>
  </link>
  <joint
    name="Joint_2"
    type="continuous">
    <origin
      xyz="0 0 -0.1308"
      rpy="-3.1379 0 0" />
    <parent
      link="Link_1" />
    <child
      link="Link_2" />
    <axis
      xyz="1 0 0" />
    <limit
      lower="-0.8"
      upper="0.8"
      effort="0"
      velocity="0" />
  </joint>
</robot>