<?xml version="1.0" encoding="utf-8"?>
<!-- This URDF was automatically created by SolidWorks to URDF Exporter! Originally created by Stephen Brawner (brawner@gmail.com) 
     Commit Version: 1.6.0-4-g7f85cfe  Build Version: 1.6.7995.38578
     For more information, please see http://wiki.ros.org/sw_urdf_exporter -->
<robot
  name="mppi">
  <link
    name="base_link">
    <inertial>
      <origin
        xyz="0.10102 0.039407 0.037655"
        rpy="0 0 0" />
      <mass
        value="1.1619" />
      <inertia
        ixx="0.0053005"
        ixy="-1.181E-09"
        ixz="8.6736E-18"
        iyy="0.010429"
        iyz="4.1088E-05"
        izz="0.0059675" />
    </inertial>
    <visual>
      <origin
        xyz="0 0 0"
        rpy="0 0 0" />
      <geometry>
        <mesh
          filename="package://mppi/meshes/base_link.STL" />
      </geometry>
      <material
        name="">
        <color
          rgba="1 1 1 1" />
      </material>
    </visual>
    <collision>
      <origin
        xyz="0 0 0"
        rpy="0 0 0" />
      <geometry>
        <mesh
          filename="package://mppi/meshes/base_link.STL" />
      </geometry>
    </collision>
  </link>
  <link
    name="Link_1">
    <inertial>
      <origin
        xyz="0.023282 -7.0854E-06 -0.08892"
        rpy="0 0 0" />
      <mass
        value="0.067836" />
      <inertia
        ixx="1.7491E-05"
        ixy="-5.233E-09"
        ixz="2.555E-07"
        iyy="2.2905E-05"
        iyz="4.4082E-09"
        izz="1.2229E-05" />
    </inertial>
    <visual>
      <origin
        xyz="0 0 0"
        rpy="0 0 0" />
      <geometry>
        <mesh
          filename="package://mppi/meshes/Link_1.STL" />
      </geometry>
      <material
        name="">
        <color
          rgba="1 0.94902 0.89804 1" />
      </material>
    </visual>
    <collision>
      <origin
        xyz="0 0 0"
        rpy="0 0 0" />
      <geometry>
        <mesh
          filename="package://mppi/meshes/Link_1.STL" />
      </geometry>
    </collision>
  </link>
  <joint
    name="Joint_1"
    type="continuous">
    <origin
      xyz="0.076125 -0.042332 -0.059398"
      rpy="-0.0039907 0 0" />
    <parent
      link="base_link" />
    <child
      link="Link_1" />
    <axis
      xyz="1 0 0" />
    <limit
      lower="-0.8"
      upper="0.8"
      effort="0"
      velocity="0" />
  </joint>
  <link
    name="Link_2">
    <inertial>
      <origin
        xyz="0.02295 1.1102E-15 0.079412"
        rpy="0 0 0" />
      <mass
        value="0.031109" />
      <inertia
        ixx="4.0466E-05"
        ixy="9.0507E-20"
        ixz="-6.0571E-20"
        iyy="4.165E-05"
        iyz="1.9238E-19"
        izz="2.8062E-05" />
    </inertial>
    <visual>
      <origin
        xyz="0 0 0"
        rpy="0 0 0" />
      <geometry>
        <mesh
          filename="package://mppi/meshes/Link_2.STL" />
      </geometry>
      <material
        name="">
        <color
          rgba="1 1 1 1" />
      </material>
    </visual>
    <collision>
      <origin
        xyz="0 0 0"
        rpy="0 0 0" />
      <geometry>
        <mesh
          filename="package://mppi/meshes/Link_2.STL" />
      </geometry>
    </collision>
  </link>
  <joint
    name="Joint_2"
    type="continuous">
    <origin
      xyz="0 0 -0.1308"
      rpy="3.1379 0 0" />
    <parent
      link="Link_1" />
    <child
      link="Link_2" />
    <axis
      xyz="1 0 0" />
    <limit
      lower="-0.8"
      upper="0.8"
      effort="0"
      velocity="0" />
  </joint>
</robot>