<?xml version="1.0" encoding="utf-8"?>
<!-- This URDF was automatically created by SolidWorks to URDF Exporter! Originally created by Stephen Brawner (brawner@gmail.com) 
     Commit Version: 1.6.0-4-g7f85cfe  Build Version: 1.6.7995.38578
     For more information, please see http://wiki.ros.org/sw_urdf_exporter -->
<robot
  name="mppi">
  <link
    name="base_link">
    <inertial>
      <origin
        xyz="0.00013417 -8.5434E-05 0.031159"
        rpy="0 0 0" />
      <mass
        value="0.12847" />
      <inertia
        ixx="6.0168E-05"
        ixy="-1.0156E-16"
        ixz="1.6017E-09"
        iyy="6.1157E-05"
        iyz="5.2439E-15"
        izz="7.1418E-05" />
    </inertial>
    <visual>
      <origin
        xyz="0 0 0"
        rpy="0 0 0" />
      <geometry>
        <mesh
          filename="package://mppi/meshes/base_link.stl" />
      </geometry>
      <material
        name="">
        <color
          rgba="0.79216 0.81961 0.93333 1" />
      </material>
    </visual>
    <collision>
      <origin
        xyz="0 0 0"
        rpy="0 0 0" />
      <geometry>
        <mesh
          filename="package://mppi/meshes/base_link.stl" />
      </geometry>
    </collision>
  </link>
  <link
    name="Link_1">
    <inertial>
      <origin
        xyz="0.00038335 6.7291E-06 -0.12912"
        rpy="0 0 0" />
      <mass
        value="0.054837" />
      <inertia
        ixx="2.1193E-05"
        ixy="-5.2444E-09"
        ixz="2.5549E-07"
        iyy="2.3318E-05"
        iyz="4.4105E-09"
        izz="7.973E-06" />
    </inertial>
    <visual>
      <origin
        xyz="0 0 0"
        rpy="0 0 0" />
      <geometry>
        <mesh
          filename="package://mppi/meshes/Link_1.stl" />
      </geometry>
      <material
        name="">
        <color
          rgba="1 1 1 1" />
      </material>
    </visual>
    <collision>
      <origin
        xyz="0 0 0"
        rpy="0 0 0" />
      <geometry>
        <mesh
          filename="package://mppi/meshes/Link_1.stl" />
      </geometry>
    </collision>
  </link>
  <joint
    name="Joint_1"
    type="continuous">
    <origin
      xyz="0 -0.0735 -0.00025"
      rpy="-0.45869 0 0" />
    <parent
      link="base_link" />
    <child
      link="Link_1" />
    <axis
      xyz="1 0 0" />
  </joint>
  <link
    name="Link_2">
    <inertial>
      <origin
        xyz="-5E-05 1.0408E-15 0.020374"
        rpy="0 0 0" />
      <mass
        value="0.0043785" />
      <inertia
        ixx="5.6602E-07"
        ixy="-4.0569E-21"
        ixz="-7.7508E-20"
        iyy="1.4685E-06"
        iyz="-5.3469E-21"
        izz="1.3899E-06" />
    </inertial>
    <visual>
      <origin
        xyz="0 0 0"
        rpy="0 0 0" />
      <geometry>
        <mesh
          filename="package://mppi/meshes/Link_2.stl" />
      </geometry>
      <material
        name="">
        <color
          rgba="1 0.75686 0.054902 1" />
      </material>
    </visual>
    <collision>
      <origin
        xyz="0 0 0"
        rpy="0 0 0" />
      <geometry>
        <mesh
          filename="package://mppi/meshes/Link_2.stl" />
      </geometry>
    </collision>
  </link>
  <joint
    name="Joint_2"
    type="continuous">
    <origin
      xyz="0 0 -0.1608"
      rpy="-3.0735 0 0" />
    <parent
      link="Link_1" />
    <child
      link="Link_2" />
    <axis
      xyz="1 0 0" />
  </joint>
</robot>