<?xml version="1.0" encoding="utf-8"?>
<!-- This URDF was automatically created by SolidWorks to URDF Exporter! Originally created by Stephen Brawner (brawner@gmail.com) 
     Commit Version: 1.6.0-4-g7f85cfe  Build Version: 1.6.7995.38578
     For more information, please see http://wiki.ros.org/sw_urdf_exporter -->
<robot
  name="Manipulator.SLDASM">
  <link
    name="base_link">
    <inertial>
      <origin
        xyz="0.00018827 -8.4948E-05 0.031073"
        rpy="0 0 0" />
      <mass
        value="0.13065" />
      <inertia
        ixx="6.1098E-05"
        ixy="8.3203E-18"
        ixz="1.181E-09"
        iyy="6.2146E-05"
        iyz="1.2581E-21"
        izz="7.2663E-05" />
    </inertial>
    <visual>
      <origin
        xyz="0 0 0"
        rpy="0 0 0" />
      <geometry>
        <mesh
          filename="package://Manipulator.SLDASM/meshes/base_link.STL" />
      </geometry>
      <material
        name="">
        <color
          rgba="1 1 1 1" />
      </material>
    </visual>
    <collision>
      <origin
        xyz="0 0 0"
        rpy="0 0 0" />
      <geometry>
        <mesh
          filename="package://Manipulator.SLDASM/meshes/base_link.STL" />
      </geometry>
    </collision>
  </link>
  <link
    name="Link_1">
    <inertial>
      <origin
        xyz="-0.0016234 -6.9776E-06 -0.11052"
        rpy="0 0 0" />
      <mass
        value="0.068872" />
      <inertia
        ixx="2.4507E-05"
        ixy="-5.2318E-09"
        ixz="2.555E-07"
        iyy="2.9945E-05"
        iyz="4.4109E-09"
        izz="1.2196E-05" />
    </inertial>
    <visual>
      <origin
        xyz="0 0 0"
        rpy="0 0 0" />
      <geometry>
        <mesh
          filename="package://Manipulator.SLDASM/meshes/Link_1.STL" />
      </geometry>
      <material
        name="">
        <color
          rgba="1 0.94902 0.89804 1" />
      </material>
    </visual>
    <collision>
      <origin
        xyz="0 0 0"
        rpy="0 0 0" />
      <geometry>
        <mesh
          filename="package://Manipulator.SLDASM/meshes/Link_1.STL" />
      </geometry>
    </collision>
  </link>
  <joint
    name="Joint_1"
    type="continuous">
    <origin
      xyz="0 -0.0735 -0.000250000000000003"
      rpy="-1.5707963267949 0 0" />
    <parent
      link="base_link" />
    <child
      link="Link_1" />
    <axis
      xyz="1 0 0" />
  </joint>
  <link
    name="Link_2">
    <inertial>
      <origin
        xyz="-0.00195 3.9378E-16 0.020374"
        rpy="0 0 0" />
      <mass
        value="0.0052104" />
      <inertia
        ixx="6.7356E-07"
        ixy="-8.9073E-21"
        ixz="-9.374E-20"
        iyy="1.7475E-06"
        iyz="-9.1902E-21"
        izz="1.654E-06" />
    </inertial>
    <visual>
      <origin
        xyz="0 0 0"
        rpy="0 0 0" />
      <geometry>
        <mesh
          filename="package://Manipulator.SLDASM/meshes/Link_2.STL" />
      </geometry>
      <material
        name="">
        <color
          rgba="1 1 1 1" />
      </material>
    </visual>
    <collision>
      <origin
        xyz="0 0 0"
        rpy="0 0 0" />
      <geometry>
        <mesh
          filename="package://Manipulator.SLDASM/meshes/Link_2.STL" />
      </geometry>
    </collision>
  </link>
  <joint
    name="Joint_2"
    type="continuous">
    <origin
      xyz="0 0 -0.1608"
      rpy="3.14159265358979 0 0" />
    <parent
      link="Link_1" />
    <child
      link="Link_2" />
    <axis
      xyz="1 0 0" />
  </joint>
</robot>